<?xml version="1.0"?>
<robot name="Cartpole">
  <link name="world">  </link>

  <joint name="world_to_sliderBar" type="fixed">
    <axis xyz="0 0 0"/>
    <origin xyz="0.0 0.0 5.0"/>
    <parent link="world"/>
    <child link="sliderBar"/>
  </joint>

  <link name="sliderBar">
    <inertial>
      <mass value="0"/>
      <inertia ixx="1.0" ixy="0.0" ixz="0.0" iyy="1.0" iyz="0.0" izz="1.0"/>
    </inertial>
  </link>

  <joint name="slider" type="prismatic">
    <axis xyz="1 0 0"/>
    <origin xyz="0.0 0.0 0.0"/>
    <parent link="sliderBar"/>
    <child link="slider"/>
    <limit effort="1000.0" lower="-15" upper="15"/>
  </joint>

  <link name="slider">
    <inertial>
      <mass value="2"/>
      <inertia ixx="2.0" ixy="0.0" ixz="0.0" iyy="1.0" iyz="0.0" izz="2.0"/>
    </inertial>
  </link>

  <joint name="rod_revolute" type="revolute">
    <axis xyz="0 1 0"/>
    <parent link="slider"/>
    <child link="rod"/>
    <origin xyz="0.0 0.0 0"/>
    <limit effort="80" lower="-6.28" upper="6.28"/>
    <dynamics damping="0.0" friction="0.0"/>
  </joint>

  <link name="rod">
    <inertial>
      <origin xyz="0 0 0.5"/>
      <mass value="5"/>
      <inertia ixx="1.0" ixy="0.0" ixz="0.0" iyy="1.0" iyz="0.0" izz="1.0"/>
    </inertial>
  </link>

  <joint name="rod_revolute2" type="revolute">
    <axis xyz="0 1 0"/>
    <parent link="slider"/>
    <child link="rod2"/>
    <origin xyz="0.0 0.0 0"/>
    <limit effort="80" lower="-6.28" upper="6.28"/>
    <dynamics damping="0.0" friction="0.0"/>
  </joint>

  <link name="rod2">
    <inertial>
      <origin xyz="0 0 0.5"/>
      <mass value="5"/>
      <inertia ixx="1.0" ixy="0.0" ixz="0.0" iyy="1.0" iyz="0.0" izz="1.0"/>
    </inertial>
  </link>
  
</robot>
